Workbook

Sheet Master
B2: MASTER
B3: 46081
B5: Code Budget | C5: Code Report (New) | D5: Area | E5: Status | F5: Tình trạng (network) | G5: Tình trạng (PMO) | H5: Store | I5: Zone | J5: Brand | K5: BR | L5: Opening date | M5: Openning date (type) | N5: Openning date per budget | O5: Openning date per revised budget | P5: Closing date | Q5: Closing date (type) | R5: Shutdown/Convert | S5: Convert to | T5: Convert from | U5: Re-Opening Date | V5: Province | W5: Area - detail
B6: 10AS5700 | C6: 10AS5700 | D6: North | E6: CLOSED | H6: Ashima 1 - 21 - 22 - 23 Điện Biên Phủ | I6: HN | J6: AS | K6: Ashima | L6: 38933 | M6: Actual | P6: 44348 | Q6: Actual | V6: HN | W6: North - Hanoi
B7: 10AS5701 | C7: 10AS5701 | D7: North | E7: ACTIVE | H7: Ashima 2 - 182 Triệu Việt Vương | I7: HN | J7: AS | K7: Ashima | L7: 39022 | M7: Actual | U7: 43677 | V7: HN | W7: North - Hanoi
B8: 10AS5702 | C8: 10AS5702 | D8: North | E8: ACTIVE | H8: Ashima 6 - 60 Giang Văn Minh | I8: HN | J8: AS | K8: Ashima | L8: 39479 | M8: Actual | V8: HN | W8: North - Hanoi
B9: 10KK4400 | C9: 10KK4400 | D9: North | E9: ACTIVE | H9: Kichi Kichi Big C | I9: HN | J9: KK | K9: Kichi Kichi | L9: 39845 | M9: Actual | V9: HN | W9: North - Hanoi
B10: 10KK4401 | C10: 10KK4401 | D10: North | E10: CLOSED | H10: Kichi Kichi Tăng Bạt Hổ | I10: HN | J10: KK | K10: Kichi Kichi | L10: 39965 | M10: Actual | P10: 44651 | Q10: Actual | V10: HN | W10: North - Hanoi
B11: 10KK4402 | C11: 10KK4402 | D11: North | E11: CLOSED | H11: Kichi Kichi Phạm Ngọc Thạch | I11: HN | J11: KK | K11: Kichi Kichi | L11: 40087 | M11: Actual | P11: 45519 | Q11: Actual | R11: SHUTDOWN | V11: HN | W11: North - Hanoi
B12: 10KK4403 | C12: 10KK4403 | D12: North | E12: ACTIVE | H12: Kichi Kichi Vincom HN | I12: HN | J12: KK | K12: Kichi Kichi | L12: 40087 | M12: Actual | V12: HN | W12: North - Hanoi
B13: 10KK4404 | C13: 10KK4404 | D13: North | E13: CLOSED | H13: Kichi Kichi Nguyễn Phong Sắc | I13: HN | J13: KK | K13: Kichi Kichi | L13: 40148 | M13: Actual | V13: HN | W13: North - Hanoi
B14: 10KK4406 | C14: 10KK4406 | D14: North | E14: CLOSED | H14: Kichi Kichi Láng Hạ | I14: HN | J14: KK | K14: Kichi Kichi | L14: 40458 | M14: Actual | P14: 45432 | Q14: Actual | R14: CONVERT | S14: 10MG4734 | V14: HN | W14: North - Hanoi
B15: 10SM4901 | C15: 10SM4901 | D15: North | E15: ACTIVE | H15: Sumo BBQ Hoàng Quốc Việt | I15: HN | J15: SM | K15: Sumo BBQ | L15: 40555 | M15: Actual | V15: HN | W15: North - Hanoi
B16: 10SM4902 | C16: 10SM4902 | D16: North | E16: CLOSED | H16: Sumo BBQ Huỳnh Thúc Kháng | I16: HN | J16: SM | K16: Sumo BBQ | L16: 40673 | M16: Actual | P16: 44287 | Q16: Actual | V16: HN | W16: North - Hanoi
B17: 10SM4903 | C17: 10SM4903 | D17: North | E17: CLOSED | H17: Sumo BBQ Quán Sứ | I17: HN | J17: SM | K17: Sumo BBQ | L17: 40754 | M17: Actual | P17: 44081 | Q17: Actual | V17: HN | W17: North - Hanoi
B18: 10SM4904 | C18: 10SM4904 | D18: North | E18: CLOSED | H18: Sumo BBQ Savico - Nguyễn Văn Linh | I18: HN | J18: SM | K18: Sumo BBQ | L18: 40893 | M18: Actual | P18: 45551 | Q18: Actual | R18: SHUTDOWN | V18: HN | W18: North - Hanoi
B19: 10SS5900 | C19: 10SS5900 | D19: North | E19: ACTIVE | H19: I Sushi Nguyễn Chí Thanh | I19: HN | J19: SS | K19: Isushi | L19: 40990 | M19: Actual | U19: 43618 | V19: HN | W19: North - Hanoi
B20: 10ST6100 | C20: 10ST6100 | D20: North | E20: CLOSED | H20: 37 Street Indochina Xuân Thủy | I20: HN | J20: ST | K20: Phố 37 | L20: 41162 | M20: Actual | P20: 45513 | Q20: Actual | R20: CONVERT | S20: 10LC4845 | U20: 44720 | V20: HN | W20: North - Hanoi
B21: 10DR6200 | C21: 10DR6200 | D21: North | E21: CLOSED | H21: Daruma Giảng Võ | I21: HN | J21: DR | K21: Daruma | L21: 41275 | M21: Actual | P21: 43901 | Q21: Actual | V21: HN | W21: North - Hanoi
B22: 10KK4405 | C22: 10KK4405 | D22: North | E22: CLOSED | H22: Kichi Kichi Trung Hòa Nhân Chính | I22: HN | J22: KK | K22: Kichi Kichi | L22: 41379 | M22: Actual | P22: 45271 | Q22: Actual | V22: HN | W22: North - Hanoi
B23: 10GG4100 | C23: 10GG4100 | D23: North | E23: ACTIVE | H23: Gogi House Big C | I23: HN | J23: GG | K23: Gogi | L23: 41438 | M23: Actual | V23: HN | W23: North - Hanoi
B24: 10GG4102 | C24: 10GG4102 | D24: North | E24: ACTIVE | H24: Gogi House Trần Thái Tông | I24: HN | J24: GG | K24: Gogi | L24: 41544 | M24: Actual | V24: HN | W24: North - Hanoi
B25: 10KK4407 | C25: 10KK4407 | D25: North | E25: ACTIVE | H25: Kichi Kichi Royal City | I25: HN | J25: KK | K25: Kichi Kichi | L25: 41557 | M25: Actual | V25: HN | W25: North - Hanoi
B26: 10SM4905 | C26: 10SM4905 | D26: North | E26: CLOSED | H26: Sumo BBQ Royal City | I26: HN | J26: SM | K26: Sumo BBQ | L26: 41557 | M26: Actual | P26: 44091 | Q26: Actual | V26: HN | W26: North - Hanoi
B27: 10GG4101 | C27: 10GG4101 | D27: North | E27: ACTIVE | H27: Gogi House Royal City | I27: HN | J27: GG | K27: Gogi | L27: 41639 | M27: Actual | V27: HN | W27: North - Hanoi
B28: 10GF4001 | C28: 10GF4001 | D28: North | E28: CLOSED | H28: Icook | I28: IC+CT | J28: GF | K28: Icook | L28: 41640 | M28: Actual | P28: 46066 | Q28: Actual | V28: IC+CT | W28: North - Hanoi
B29: 10SM4906 | C29: 10SM4906 | D29: North | E29: CLOSED | H29: Sumo BBQ Tô Hiến Thành | I29: HN | J29: SM | K29: Sumo BBQ | L29: 41652 | M29: Actual | P29: 45418 | Q29: Actual | R29: SHUTDOWN | V29: HN | W29: North - Hanoi
B30: 10VV5300 | C30: 10VV5300 | D30: North | E30: ACTIVE | H30: Vuvuzela Trung Hòa Nhân Chính | I30: HN | J30: VV | K30: Vuvuzela | L30: 41679 | M30: Actual | V30: HN | W30: North - Hanoi
B31: 10GG4103 | C31: 10GG4103 | D31: North | E31: CLOSED | H31: Gogi House Mipec | I31: HN | J31: GG | K31: Gogi | L31: 41725 | M31: Actual | P31: 44362 | Q31: Actual | V31: HN | W31: North - Hanoi
B32: 10VV5310 | C32: 10VV5310 | D32: North | E32: CLOSED | H32: Vuvuzela Tràng Thi | I32: HN | J32: VV | K32: Vuvuzela | L32: 41751 | M32: Actual | P32: 45458 | Q32: Actual | R32: SHUTDOWN | V32: HN | W32: North - Hanoi
B33: 10GG4104 | C33: 10GG4104 | D33: North | E33: CLOSED | H33: Gogi House Phạm Ngọc Thạch | I33: HN | J33: GG | K33: Gogi | L33: 41806 | M33: Actual | P33: 44530 | Q33: Actual | V33: HN | W33: North - Hanoi
B34: 10SM4900 | C34: 10SM4900 | D34: North | E34: CLOSED | H34: Sumo BBQ Big C | I34: HN | J34: SM | K34: Sumo BBQ | L34: 41855 | M34: Actual | P34: 45593 | Q34: Actual | R34: SHUTDOWN | U34: 43733 | V34: HN | W34: North - Hanoi
B35: 10GG4128 | C35: 10GG4128 | D35: North | E35: ACTIVE | H35: Gogi House Hạ Long | I35: QN | J35: GG | K35: Gogi | L35: 41931 | M35: Actual | V35: QN | W35: North - Other Cities
B36: 10GG4105 | C36: 10GG4105 | D36: North | E36: ACTIVE | H36: Gogi House Bùi Thị Xuân | I36: HN | J36: GG | K36: Gogi | L36: 42000 | M36: Actual | V36: HN | W36: North - Hanoi
B37: 10MW5117 | C37: 10MW5117 | D37: North | E37: CLOSED | H37: MW Nguyễn Hoàng | I37: HN | J37: MW | K37: MANWAH | L37: 43709 | M37: Actual | P37: 45658 | Q37: Actual | R37: SHUTDOWN | V37: HN | W37: North - Hanoi
B38: 10VV5308 | C38: 10VV5308 | D38: North | E38: ACTIVE | H38: Vuvuzela Nguyễn Trãi | I38: HN | J38: VV | K38: Vuvuzela | L38: 42017 | M38: Actual | U38: 43976 | V38: HN | W38: North - Hanoi
B39: 10GG4106 | C39: 10GG4106 | D39: North | E39: ACTIVE | H39: Gogi House Trung Yên | I39: HN | J39: GG | K39: Gogi | L39: 42035 | M39: Actual | V39: HN | W39: North - Hanoi
B40: 10CB5400 | C40: 10CB5400 | D40: North | E40: CLOSED | H40: Cowboy jack's Trung Hòa Nhân chính | I40: HN | J40: CB | K40: Cowboy Jack | L40: 42092 | M40: Actual | P40: 44927 | Q40: Actual | V40: HN | W40: North - Hanoi
B41: 10HT4700 | C41: 10HT4700 | D41: North | E41: CLOSED | H41: Hutong Big C Thăng Long | I41: HN | J41: HT | K41: Hutong | L41: 42121 | M41: Actual | P41: 43900 | Q41: Actual | V41: HN | W41: North - Hanoi
B42: 10DR6202 | C42: 10DR6202 | D42: North | E42: CLOSED | H42: Daruma Trung Hòa Nhân Chính | I42: HN | J42: DR | K42: Daruma | L42: 42197 | M42: Actual | P42: 43811 | Q42: Actual | V42: HN | W42: North - Hanoi
...

Sheet Master MoM
F1: 46053 | G1: 46081 | H1: 46112 | I1: 46142 | J1: 46173 | K1: 46203 | L1: 46234 | M1: 46265 | N1: 46295 | O1: 46326 | P1: 46356 | Q1: 46387
C2: PC | D2: Openning date | E2: Closing date | F2: Jan | G2: Feb | H2: March | I2: April | J2: May | K2: June | L2: July | M2: August | N2: Sept | O2: Oct | P2: Nov | Q2: Dec
B3: {=_xlfn._xlws.FILTER( Master!B:B, ( (Master!M:M="Actual")*(Master!E:E="Active")*ISNUMBER(Master!L:L)*(Master!L:L>0) + (Master!M:M="Forecast")*ISNUMBER(Master!L:L)*(Master!L:L>0) ) )} -> 10AS5701 | C3: =VLOOKUP(B3,Master!B:C,2,0) -> 10AS5701 | D3: =VLOOKUP(B3,Master!B:L,11,0) -> 39022 | E3: =VLOOKUP(B3,Master!B:P,15,0) -> 0 | F3: =IF($E3>0,"CLOSED",IF($D3<F$1,"ACTIVE","WAITING FOR OPEN")) -> ACTIVE | G3: =IF($E3>0,"CLOSED",IF($D3<G$1,"ACTIVE","WAITING FOR OPEN")) -> ACTIVE | H3: =IF($E3>0,"CLOSED",IF($D3<H$1,"ACTIVE","WAITING FOR OPEN")) -> ACTIVE | I3: =IF($E3>0,"CLOSED",IF($D3<I$1,"ACTIVE","WAITING FOR OPEN")) -> ACTIVE | J3: =IF($E3>0,"CLOSED",IF($D3<J$1,"ACTIVE","WAITING FOR OPEN")) -> ACTIVE | K3: =IF($E3>0,"CLOSED",IF($D3<K$1,"ACTIVE","WAITING FOR OPEN")) -> ACTIVE | L3: =IF($E3>0,"CLOSED",IF($D3<L$1,"ACTIVE","WAITING FOR OPEN")) -> ACTIVE | M3: =IF($E3>0,"CLOSED",IF($D3<M$1,"ACTIVE","WAITING FOR OPEN")) -> ACTIVE | ... Q3: =IF($E3>0,"CLOSED",IF($D3<Q$1,"ACTIVE","WAITING FOR OPEN")) -> ACTIVE
B4: 10AS5702 | C4: =VLOOKUP(B4,Master!B:C,2,0) -> 10AS5702 | D4: =VLOOKUP(B4,Master!B:L,11,0) -> 39479 | E4: =VLOOKUP(B4,Master!B:P,15,0) -> 0 | F4: =IF($E4>0,"CLOSED",IF($D4<F$1,"ACTIVE","WAITING FOR OPEN")) -> ACTIVE | G4: =IF($E4>0,"CLOSED",IF($D4<G$1,"ACTIVE","WAITING FOR OPEN")) -> ACTIVE | H4: =IF($E4>0,"CLOSED",IF($D4<H$1,"ACTIVE","WAITING FOR OPEN")) -> ACTIVE | I4: =IF($E4>0,"CLOSED",IF($D4<I$1,"ACTIVE","WAITING FOR OPEN")) -> ACTIVE | J4: =IF($E4>0,"CLOSED",IF($D4<J$1,"ACTIVE","WAITING FOR OPEN")) -> ACTIVE | K4: =IF($E4>0,"CLOSED",IF($D4<K$1,"ACTIVE","WAITING FOR OPEN")) -> ACTIVE | L4: =IF($E4>0,"CLOSED",IF($D4<L$1,"ACTIVE","WAITING FOR OPEN")) -> ACTIVE | M4: =IF($E4>0,"CLOSED",IF($D4<M$1,"ACTIVE","WAITING FOR OPEN")) -> ACTIVE | ... Q4: =IF($E4>0,"CLOSED",IF($D4<Q$1,"ACTIVE","WAITING FOR OPEN")) -> ACTIVE
B5: 10KK4400 | C5: =VLOOKUP(B5,Master!B:C,2,0) -> 10KK4400 | D5: =VLOOKUP(B5,Master!B:L,11,0) -> 39845 | E5: =VLOOKUP(B5,Master!B:P,15,0) -> 0 | F5: =IF($E5>0,"CLOSED",IF($D5<F$1,"ACTIVE","WAITING FOR OPEN")) -> ACTIVE | G5: =IF($E5>0,"CLOSED",IF($D5<G$1,"ACTIVE","WAITING FOR OPEN")) -> ACTIVE | H5: =IF($E5>0,"CLOSED",IF($D5<H$1,"ACTIVE","WAITING FOR OPEN")) -> ACTIVE | I5: =IF($E5>0,"CLOSED",IF($D5<I$1,"ACTIVE","WAITING FOR OPEN")) -> ACTIVE | J5: =IF($E5>0,"CLOSED",IF($D5<J$1,"ACTIVE","WAITING FOR OPEN")) -> ACTIVE | K5: =IF($E5>0,"CLOSED",IF($D5<K$1,"ACTIVE","WAITING FOR OPEN")) -> ACTIVE | L5: =IF($E5>0,"CLOSED",IF($D5<L$1,"ACTIVE","WAITING FOR OPEN")) -> ACTIVE | M5: =IF($E5>0,"CLOSED",IF($D5<M$1,"ACTIVE","WAITING FOR OPEN")) -> ACTIVE | ... Q5: =IF($E5>0,"CLOSED",IF($D5<Q$1,"ACTIVE","WAITING FOR OPEN")) -> ACTIVE
B6: 10KK4403 | C6: =VLOOKUP(B6,Master!B:C,2,0) -> 10KK4403 | D6: =VLOOKUP(B6,Master!B:L,11,0) -> 40087 | E6: =VLOOKUP(B6,Master!B:P,15,0) -> 0 | F6: =IF($E6>0,"CLOSED",IF($D6<F$1,"ACTIVE","WAITING FOR OPEN")) -> ACTIVE | G6: =IF($E6>0,"CLOSED",IF($D6<G$1,"ACTIVE","WAITING FOR OPEN")) -> ACTIVE | H6: =IF($E6>0,"CLOSED",IF($D6<H$1,"ACTIVE","WAITING FOR OPEN")) -> ACTIVE | I6: =IF($E6>0,"CLOSED",IF($D6<I$1,"ACTIVE","WAITING FOR OPEN")) -> ACTIVE | J6: =IF($E6>0,"CLOSED",IF($D6<J$1,"ACTIVE","WAITING FOR OPEN")) -> ACTIVE | K6: =IF($E6>0,"CLOSED",IF($D6<K$1,"ACTIVE","WAITING FOR OPEN")) -> ACTIVE | L6: =IF($E6>0,"CLOSED",IF($D6<L$1,"ACTIVE","WAITING FOR OPEN")) -> ACTIVE | M6: =IF($E6>0,"CLOSED",IF($D6<M$1,"ACTIVE","WAITING FOR OPEN")) -> ACTIVE | ... Q6: =IF($E6>0,"CLOSED",IF($D6<Q$1,"ACTIVE","WAITING FOR OPEN")) -> ACTIVE
B7: 10SM4901 | C7: =VLOOKUP(B7,Master!B:C,2,0) -> 10SM4901 | D7: =VLOOKUP(B7,Master!B:L,11,0) -> 40555 | E7: =VLOOKUP(B7,Master!B:P,15,0) -> 0 | F7: =IF($E7>0,"CLOSED",IF($D7<F$1,"ACTIVE","WAITING FOR OPEN")) -> ACTIVE | G7: =IF($E7>0,"CLOSED",IF($D7<G$1,"ACTIVE","WAITING FOR OPEN")) -> ACTIVE | H7: =IF($E7>0,"CLOSED",IF($D7<H$1,"ACTIVE","WAITING FOR OPEN")) -> ACTIVE | I7: =IF($E7>0,"CLOSED",IF($D7<I$1,"ACTIVE","WAITING FOR OPEN")) -> ACTIVE | J7: =IF($E7>0,"CLOSED",IF($D7<J$1,"ACTIVE","WAITING FOR OPEN")) -> ACTIVE | K7: =IF($E7>0,"CLOSED",IF($D7<K$1,"ACTIVE","WAITING FOR OPEN")) -> ACTIVE | L7: =IF($E7>0,"CLOSED",IF($D7<L$1,"ACTIVE","WAITING FOR OPEN")) -> ACTIVE | M7: =IF($E7>0,"CLOSED",IF($D7<M$1,"ACTIVE","WAITING FOR OPEN")) -> ACTIVE | ... Q7: =IF($E7>0,"CLOSED",IF($D7<Q$1,"ACTIVE","WAITING FOR OPEN")) -> ACTIVE
B8: 10SS5900 | C8: =VLOOKUP(B8,Master!B:C,2,0) -> 10SS5900 | D8: =VLOOKUP(B8,Master!B:L,11,0) -> 40990 | E8: =VLOOKUP(B8,Master!B:P,15,0) -> 0 | F8: =IF($E8>0,"CLOSED",IF($D8<F$1,"ACTIVE","WAITING FOR OPEN")) -> ACTIVE | G8: =IF($E8>0,"CLOSED",IF($D8<G$1,"ACTIVE","WAITING FOR OPEN")) -> ACTIVE | H8: =IF($E8>0,"CLOSED",IF($D8<H$1,"ACTIVE","WAITING FOR OPEN")) -> ACTIVE | I8: =IF($E8>0,"CLOSED",IF($D8<I$1,"ACTIVE","WAITING FOR OPEN")) -> ACTIVE | J8: =IF($E8>0,"CLOSED",IF($D8<J$1,"ACTIVE","WAITING FOR OPEN")) -> ACTIVE | K8: =IF($E8>0,"CLOSED",IF($D8<K$1,"ACTIVE","WAITING FOR OPEN")) -> ACTIVE | L8: =IF($E8>0,"CLOSED",IF($D8<L$1,"ACTIVE","WAITING FOR OPEN")) -> ACTIVE | M8: =IF($E8>0,"CLOSED",IF($D8<M$1,"ACTIVE","WAITING FOR OPEN")) -> ACTIVE | ... Q8: =IF($E8>0,"CLOSED",IF($D8<Q$1,"ACTIVE","WAITING FOR OPEN")) -> ACTIVE
B9: 10GG4100 | C9: =VLOOKUP(B9,Master!B:C,2,0) -> 10GG4100 | D9: =VLOOKUP(B9,Master!B:L,11,0) -> 41438 | E9: =VLOOKUP(B9,Master!B:P,15,0) -> 0 | F9: =IF($E9>0,"CLOSED",IF($D9<F$1,"ACTIVE","WAITING FOR OPEN")) -> ACTIVE | G9: =IF($E9>0,"CLOSED",IF($D9<G$1,"ACTIVE","WAITING FOR OPEN")) -> ACTIVE | H9: =IF($E9>0,"CLOSED",IF($D9<H$1,"ACTIVE","WAITING FOR OPEN")) -> ACTIVE | I9: =IF($E9>0,"CLOSED",IF($D9<I$1,"ACTIVE","WAITING FOR OPEN")) -> ACTIVE | J9: =IF($E9>0,"CLOSED",IF($D9<J$1,"ACTIVE","WAITING FOR OPEN")) -> ACTIVE | K9: =IF($E9>0,"CLOSED",IF($D9<K$1,"ACTIVE","WAITING FOR OPEN")) -> ACTIVE | L9: =IF($E9>0,"CLOSED",IF($D9<L$1,"ACTIVE","WAITING FOR OPEN")) -> ACTIVE | M9: =IF($E9>0,"CLOSED",IF($D9<M$1,"ACTIVE","WAITING FOR OPEN")) -> ACTIVE | ... Q9: =IF($E9>0,"CLOSED",IF($D9<Q$1,"ACTIVE","WAITING FOR OPEN")) -> ACTIVE
B10: 10GG4102 | C10: =VLOOKUP(B10,Master!B:C,2,0) -> 10GG4102 | D10: =VLOOKUP(B10,Master!B:L,11,0) -> 41544 | E10: =VLOOKUP(B10,Master!B:P,15,0) -> 0 | F10: =IF($E10>0,"CLOSED",IF($D10<F$1,"ACTIVE","WAITING FOR OPEN")) -> ACTIVE | G10: =IF($E10>0,"CLOSED",IF($D10<G$1,"ACTIVE","WAITING FOR OPEN")) -> ACTIVE | H10: =IF($E10>0,"CLOSED",IF($D10<H$1,"ACTIVE","WAITING FOR OPEN")) -> ACTIVE | I10: =IF($E10>0,"CLOSED",IF($D10<I$1,"ACTIVE","WAITING FOR OPEN")) -> ACTIVE | J10: =IF($E10>0,"CLOSED",IF($D10<J$1,"ACTIVE","WAITING FOR OPEN")) -> ACTIVE | K10: =IF($E10>0,"CLOSED",IF($D10<K$1,"ACTIVE","WAITING FOR OPEN")) -> ACTIVE | L10: =IF($E10>0,"CLOSED",IF($D10<L$1,"ACTIVE","WAITING FOR OPEN")) -> ACTIVE | M10: =IF($E10>0,"CLOSED",IF($D10<M$1,"ACTIVE","WAITING FOR OPEN")) -> ACTIVE | ... Q10: =IF($E10>0,"CLOSED",IF($D10<Q$1,"ACTIVE","WAITING FOR OPEN")) -> ACTIVE
B11: 10KK4407 | C11: =VLOOKUP(B11,Master!B:C,2,0) -> 10KK4407 | D11: =VLOOKUP(B11,Master!B:L,11,0) -> 41557 | E11: =VLOOKUP(B11,Master!B:P,15,0) -> 0 | F11: =IF($E11>0,"CLOSED",IF($D11<F$1,"ACTIVE","WAITING FOR OPEN")) -> ACTIVE | G11: =IF($E11>0,"CLOSED",IF($D11<G$1,"ACTIVE","WAITING FOR OPEN")) -> ACTIVE | H11: =IF($E11>0,"CLOSED",IF($D11<H$1,"ACTIVE","WAITING FOR OPEN")) -> ACTIVE | I11: =IF($E11>0,"CLOSED",IF($D11<I$1,"ACTIVE","WAITING FOR OPEN")) -> ACTIVE | J11: =IF($E11>0,"CLOSED",IF($D11<J$1,"ACTIVE","WAITING FOR OPEN")) -> ACTIVE | K11: =IF($E11>0,"CLOSED",IF($D11<K$1,"ACTIVE","WAITING FOR OPEN")) -> ACTIVE | L11: =IF($E11>0,"CLOSED",IF($D11<L$1,"ACTIVE","WAITING FOR OPEN")) -> ACTIVE | M11: =IF($E11>0,"CLOSED",IF($D11<M$1,"ACTIVE","WAITING FOR OPEN")) -> ACTIVE | ... Q11: =IF($E11>0,"CLOSED",IF($D11<Q$1,"ACTIVE","WAITING FOR OPEN")) -> ACTIVE
B12: 10GG4101 | C12: =VLOOKUP(B12,Master!B:C,2,0) -> 10GG4101 | D12: =VLOOKUP(B12,Master!B:L,11,0) -> 41639 | E12: =VLOOKUP(B12,Master!B:P,15,0) -> 0 | F12: =IF($E12>0,"CLOSED",IF($D12<F$1,"ACTIVE","WAITING FOR OPEN")) -> ACTIVE | G12: =IF($E12>0,"CLOSED",IF($D12<G$1,"ACTIVE","WAITING FOR OPEN")) -> ACTIVE | H12: =IF($E12>0,"CLOSED",IF($D12<H$1,"ACTIVE","WAITING FOR OPEN")) -> ACTIVE | I12: =IF($E12>0,"CLOSED",IF($D12<I$1,"ACTIVE","WAITING FOR OPEN")) -> ACTIVE | J12: =IF($E12>0,"CLOSED",IF($D12<J$1,"ACTIVE","WAITING FOR OPEN")) -> ACTIVE | K12: =IF($E12>0,"CLOSED",IF($D12<K$1,"ACTIVE","WAITING FOR OPEN")) -> ACTIVE | L12: =IF($E12>0,"CLOSED",IF($D12<L$1,"ACTIVE","WAITING FOR OPEN")) -> ACTIVE | M12: =IF($E12>0,"CLOSED",IF($D12<M$1,"ACTIVE","WAITING FOR OPEN")) -> ACTIVE | ... Q12: =IF($E12>0,"CLOSED",IF($D12<Q$1,"ACTIVE","WAITING FOR OPEN")) -> ACTIVE
B13: 10VV5300 | C13: =VLOOKUP(B13,Master!B:C,2,0) -> 10VV5300 | D13: =VLOOKUP(B13,Master!B:L,11,0) -> 41679 | E13: =VLOOKUP(B13,Master!B:P,15,0) -> 0 | F13: =IF($E13>0,"CLOSED",IF($D13<F$1,"ACTIVE","WAITING FOR OPEN")) -> ACTIVE | G13: =IF($E13>0,"CLOSED",IF($D13<G$1,"ACTIVE","WAITING FOR OPEN")) -> ACTIVE | H13: =IF($E13>0,"CLOSED",IF($D13<H$1,"ACTIVE","WAITING FOR OPEN")) -> ACTIVE | I13: =IF($E13>0,"CLOSED",IF($D13<I$1,"ACTIVE","WAITING FOR OPEN")) -> ACTIVE | J13: =IF($E13>0,"CLOSED",IF($D13<J$1,"ACTIVE","WAITING FOR OPEN")) -> ACTIVE | K13: =IF($E13>0,"CLOSED",IF($D13<K$1,"ACTIVE","WAITING FOR OPEN")) -> ACTIVE | L13: =IF($E13>0,"CLOSED",IF($D13<L$1,"ACTIVE","WAITING FOR OPEN")) -> ACTIVE | M13: =IF($E13>0,"CLOSED",IF($D13<M$1,"ACTIVE","WAITING FOR OPEN")) -> ACTIVE | ... Q13: =IF($E13>0,"CLOSED",IF($D13<Q$1,"ACTIVE","WAITING FOR OPEN")) -> ACTIVE
B14: 10GG4128 | C14: =VLOOKUP(B14,Master!B:C,2,0) -> 10GG4128 | D14: =VLOOKUP(B14,Master!B:L,11,0) -> 41931 | E14: =VLOOKUP(B14,Master!B:P,15,0) -> 0 | F14: =IF($E14>0,"CLOSED",IF($D14<F$1,"ACTIVE","WAITING FOR OPEN")) -> ACTIVE | G14: =IF($E14>0,"CLOSED",IF($D14<G$1,"ACTIVE","WAITING FOR OPEN")) -> ACTIVE | H14: =IF($E14>0,"CLOSED",IF($D14<H$1,"ACTIVE","WAITING FOR OPEN")) -> ACTIVE | I14: =IF($E14>0,"CLOSED",IF($D14<I$1,"ACTIVE","WAITING FOR OPEN")) -> ACTIVE | J14: =IF($E14>0,"CLOSED",IF($D14<J$1,"ACTIVE","WAITING FOR OPEN")) -> ACTIVE | K14: =IF($E14>0,"CLOSED",IF($D14<K$1,"ACTIVE","WAITING FOR OPEN")) -> ACTIVE | L14: =IF($E14>0,"CLOSED",IF($D14<L$1,"ACTIVE","WAITING FOR OPEN")) -> ACTIVE | M14: =IF($E14>0,"CLOSED",IF($D14<M$1,"ACTIVE","WAITING FOR OPEN")) -> ACTIVE | ... Q14: =IF($E14>0,"CLOSED",IF($D14<Q$1,"ACTIVE","WAITING FOR OPEN")) -> ACTIVE
B15: 10GG4105 | C15: =VLOOKUP(B15,Master!B:C,2,0) -> 10GG4105 | D15: =VLOOKUP(B15,Master!B:L,11,0) -> 42000 | E15: =VLOOKUP(B15,Master!B:P,15,0) -> 0 | F15: =IF($E15>0,"CLOSED",IF($D15<F$1,"ACTIVE","WAITING FOR OPEN")) -> ACTIVE | G15: =IF($E15>0,"CLOSED",IF($D15<G$1,"ACTIVE","WAITING FOR OPEN")) -> ACTIVE | H15: =IF($E15>0,"CLOSED",IF($D15<H$1,"ACTIVE","WAITING FOR OPEN")) -> ACTIVE | I15: =IF($E15>0,"CLOSED",IF($D15<I$1,"ACTIVE","WAITING FOR OPEN")) -> ACTIVE | J15: =IF($E15>0,"CLOSED",IF($D15<J$1,"ACTIVE","WAITING FOR OPEN")) -> ACTIVE | K15: =IF($E15>0,"CLOSED",IF($D15<K$1,"ACTIVE","WAITING FOR OPEN")) -> ACTIVE | L15: =IF($E15>0,"CLOSED",IF($D15<L$1,"ACTIVE","WAITING FOR OPEN")) -> ACTIVE | M15: =IF($E15>0,"CLOSED",IF($D15<M$1,"ACTIVE","WAITING FOR OPEN")) -> ACTIVE | ... Q15: =IF($E15>0,"CLOSED",IF($D15<Q$1,"ACTIVE","WAITING FOR OPEN")) -> ACTIVE
... B561: 30UP4954 | C561: =VLOOKUP(B561,Master!B:C,2,0) -> 30UP4954 | D561: =VLOOKUP(B561,Master!B:L,11,0) -> 46048 | E561: =VLOOKUP(B561,Master!B:P,15,0) -> 0 | F561: =IF($E561>0,"CLOSED",IF($D561<F$1,"ACTIVE","WAITING FOR OPEN")) -> ACTIVE | G561: =IF($E561>0,"CLOSED",IF($D561<G$1,"ACTIVE","WAITING FOR OPEN")) -> ACTIVE | H561: =IF($E561>0,"CLOSED",IF($D561<H$1,"ACTIVE","WAITING FOR OPEN")) -> ACTIVE | I561: =IF($E561>0,"CLOSED",IF($D561<I$1,"ACTIVE","WAITING FOR OPEN")) -> ACTIVE | J561: =IF($E561>0,"CLOSED",IF($D561<J$1,"ACTIVE","WAITING FOR OPEN")) -> ACTIVE | K561: =IF($E561>0,"CLOSED",IF($D561<K$1,"ACTIVE","WAITING FOR OPEN")) -> ACTIVE | L561: =IF($E561>0,"CLOSED",IF($D561<L$1,"ACTIVE","WAITING FOR OPEN")) -> ACTIVE | M561: =IF($E561>0,"CLOSED",IF($D561<M$1,"ACTIVE","WAITING FOR OPEN")) -> ACTIVE | ... Q561: =IF($E561>0,"CLOSED",IF($D561<Q$1,"ACTIVE","WAITING FOR OPEN")) -> ACTIVE
B562: 2010319 | C562: =VLOOKUP(B562,Master!B:C,2,0) -> 2010319 | D562: =VLOOKUP(B562,Master!B:L,11,0) -> 45972 | E562: =VLOOKUP(B562,Master!B:P,15,0) -> 0 | F562: =IF($E562>0,"CLOSED",IF($D562<F$1,"ACTIVE","WAITING FOR OPEN")) -> ACTIVE | G562: =IF($E562>0,"CLOSED",IF($D562<G$1,"ACTIVE","WAITING FOR OPEN")) -> ACTIVE | H562: =IF($E562>0,"CLOSED",IF($D562<H$1,"ACTIVE","WAITING FOR OPEN")) -> ACTIVE | I562: =IF($E562>0,"CLOSED",IF($D562<I$1,"ACTIVE","WAITING FOR OPEN")) -> ACTIVE | J562: =IF($E562>0,"CLOSED",IF($D562<J$1,"ACTIVE","WAITING FOR OPEN")) -> ACTIVE | K562: =IF($E562>0,"CLOSED",IF($D562<K$1,"ACTIVE","WAITING FOR OPEN")) -> ACTIVE | L562: =IF($E562>0,"CLOSED",IF($D562<L$1,"ACTIVE","WAITING FOR OPEN")) -> ACTIVE | M562: =IF($E562>0,"CLOSED",IF($D562<M$1,"ACTIVE","WAITING FOR OPEN")) -> ACTIVE | ... Q562: =IF($E562>0,"CLOSED",IF($D562<Q$1,"ACTIVE","WAITING FOR OPEN")) -> ACTIVE
B563: 10CV5020 | C563: =VLOOKUP(B563,Master!B:C,2,0) -> 10CV5020 | D563: =VLOOKUP(B563,Master!B:L,11,0) -> 46023 | E563: =VLOOKUP(B563,Master!B:P,15,0) -> 0 | F563: =IF($E563>0,"CLOSED",IF($D563<F$1,"ACTIVE","WAITING FOR OPEN")) -> ACTIVE | G563: =IF($E563>0,"CLOSED",IF($D563<G$1,"ACTIVE","WAITING FOR OPEN")) -> ACTIVE | H563: =IF($E563>0,"CLOSED",IF($D563<H$1,"ACTIVE","WAITING FOR OPEN")) -> ACTIVE | I563: =IF($E563>0,"CLOSED",IF($D563<I$1,"ACTIVE","WAITING FOR OPEN")) -> ACTIVE | J563: =IF($E563>0,"CLOSED",IF($D563<J$1,"ACTIVE","WAITING FOR OPEN")) -> ACTIVE | K563: =IF($E563>0,"CLOSED",IF($D563<K$1,"ACTIVE","WAITING FOR OPEN")) -> ACTIVE | L563: =IF($E563>0,"CLOSED",IF($D563<L$1,"ACTIVE","WAITING FOR OPEN")) -> ACTIVE | M563: =IF($E563>0,"CLOSED",IF($D563<M$1,"ACTIVE","WAITING FOR OPEN")) -> ACTIVE | ... Q563: =IF($E563>0,"CLOSED",IF($D563<Q$1,"ACTIVE","WAITING FOR OPEN")) -> ACTIVE
B564: 10DNNOBUD03 | C564: =VLOOKUP(B564,Master!B:C,2,0) -> 10DN5016 | D564: =VLOOKUP(B564,Master!B:L,11,0) -> 46075 | E564: =VLOOKUP(B564,Master!B:P,15,0) -> 0 | F564: =IF($E564>0,"CLOSED",IF($D564<F$1,"ACTIVE","WAITING FOR OPEN")) -> WAITING FOR OPEN | G564: =IF($E564>0,"CLOSED",IF($D564<G$1,"ACTIVE","WAITING FOR OPEN")) -> ACTIVE | H564: =IF($E564>0,"CLOSED",IF($D564<H$1,"ACTIVE","WAITING FOR OPEN")) -> ACTIVE | I564: =IF($E564>0,"CLOSED",IF($D564<I$1,"ACTIVE","WAITING FOR OPEN")) -> ACTIVE | J564: =IF($E564>0,"CLOSED",IF($D564<J$1,"ACTIVE","WAITING FOR OPEN")) -> ACTIVE | K564: =IF($E564>0,"CLOSED",IF($D564<K$1,"ACTIVE","WAITING FOR OPEN")) -> ACTIVE | L564: =IF($E564>0,"CLOSED",IF($D564<L$1,"ACTIVE","WAITING FOR OPEN")) -> ACTIVE | M564: =IF($E564>0,"CLOSED",IF($D564<M$1,"ACTIVE","WAITING FOR OPEN")) -> ACTIVE | ... Q564: =IF($E564>0,"CLOSED",IF($D564<Q$1,"ACTIVE","WAITING FOR OPEN")) -> ACTIVE
B565: 10UPNOBUD05 | C565: =VLOOKUP(B565,Master!B:C,2,0) -> 10UP5044 | D565: =VLOOKUP(B565,Master!B:L,11,0) -> 46060 | E565: =VLOOKUP(B565,Master!B:P,15,0) -> 0 | F565: =IF($E565>0,"CLOSED",IF($D565<F$1,"ACTIVE","WAITING FOR OPEN")) -> WAITING FOR OPEN | G565: =IF($E565>0,"CLOSED",IF($D565<G$1,"ACTIVE","WAITING FOR OPEN")) -> ACTIVE | H565: =IF($E565>0,"CLOSED",IF($D565<H$1,"ACTIVE","WAITING FOR OPEN")) -> ACTIVE | I565: =IF($E565>0,"CLOSED",IF($D565<I$1,"ACTIVE","WAITING FOR OPEN")) -> ACTIVE | J565: =IF($E565>0,"CLOSED",IF($D565<J$1,"ACTIVE","WAITING FOR OPEN")) -> ACTIVE | K565: =IF($E565>0,"CLOSED",IF($D565<K$1,"ACTIVE","WAITING FOR OPEN")) -> ACTIVE | L565: =IF($E565>0,"CLOSED",IF($D565<L$1,"ACTIVE","WAITING FOR OPEN")) -> ACTIVE | M565: =IF($E565>0,"CLOSED",IF($D565<M$1,"ACTIVE","WAITING FOR OPEN")) -> ACTIVE | ... Q565: =IF($E565>0,"CLOSED",IF($D565<Q$1,"ACTIVE","WAITING FOR OPEN")) -> ACTIVE
B566: 30CJ4992 | C566: =VLOOKUP(B566,Master!B:C,2,0) -> 30CJ4992 | D566: =VLOOKUP(B566,Master!B:L,11,0) -> 46044 | E566: =VLOOKUP(B566,Master!B:P,15,0) -> 0 | F566: =IF($E566>0,"CLOSED",IF($D566<F$1,"ACTIVE","WAITING FOR OPEN")) -> ACTIVE | G566: =IF($E566>0,"CLOSED",IF($D566<G$1,"ACTIVE","WAITING FOR OPEN")) -> ACTIVE | H566: =IF($E566>0,"CLOSED",IF($D566<H$1,"ACTIVE","WAITING FOR OPEN")) -> ACTIVE | I566: =IF($E566>0,"CLOSED",IF($D566<I$1,"ACTIVE","WAITING FOR OPEN")) -> ACTIVE | J566: =IF($E566>0,"CLOSED",IF($D566<J$1,"ACTIVE","WAITING FOR OPEN")) -> ACTIVE | K566: =IF($E566>0,"CLOSED",IF($D566<K$1,"ACTIVE","WAITING FOR OPEN")) -> ACTIVE | L566: =IF($E566>0,"CLOSED",IF($D566<L$1,"ACTIVE","WAITING FOR OPEN")) -> ACTIVE | M566: =IF($E566>0,"CLOSED",IF($D566<M$1,"ACTIVE","WAITING FOR OPEN")) -> ACTIVE | ... Q566: =IF($E566>0,"CLOSED",IF($D566<Q$1,"ACTIVE","WAITING FOR OPEN")) -> ACTIVE
B567: 30YTNOBUD01 | C567: =VLOOKUP(B567,Master!B:C,2,0) -> 30YT4982 | D567: =VLOOKUP(B567,Master!B:L,11,0) -> 46073 | E567: =VLOOKUP(B567,Master!B:P,15,0) -> 0 | F567: =IF($E567>0,"CLOSED",IF($D567<F$1,"ACTIVE","WAITING FOR OPEN")) -> WAITING FOR OPEN | G567: =IF($E567>0,"CLOSED",IF($D567<G$1,"ACTIVE","WAITING FOR OPEN")) -> ACTIVE | H567: =IF($E567>0,"CLOSED",IF($D567<H$1,"ACTIVE","WAITING FOR OPEN")) -> ACTIVE | I567: =IF($E567>0,"CLOSED",IF($D567<I$1,"ACTIVE","WAITING FOR OPEN")) -> ACTIVE | J567: =IF($E567>0,"CLOSED",IF($D567<J$1,"ACTIVE","WAITING FOR OPEN")) -> ACTIVE | K567: =IF($E567>0,"CLOSED",IF($D567<K$1,"ACTIVE","WAITING FOR OPEN")) -> ACTIVE | L567: =IF($E567>0,"CLOSED",IF($D567<L$1,"ACTIVE","WAITING FOR OPEN")) -> ACTIVE | M567: =IF($E567>0,"CLOSED",IF($D567<M$1,"ACTIVE","WAITING FOR OPEN")) -> ACTIVE | ... Q567: =IF($E567>0,"CLOSED",IF($D567<Q$1,"ACTIVE","WAITING FOR OPEN")) -> ACTIVE
B568: 2011005 | C568: =VLOOKUP(B568,Master!B:C,2,0) -> 2011005 | D568: =VLOOKUP(B568,Master!B:L,11,0) -> 45981 | E568: =VLOOKUP(B568,Master!B:P,15,0) -> 0 | F568: =IF($E568>0,"CLOSED",IF($D568<F$1,"ACTIVE","WAITING FOR OPEN")) -> ACTIVE | G568: =IF($E568>0,"CLOSED",IF($D568<G$1,"ACTIVE","WAITING FOR OPEN")) -> ACTIVE | H568: =IF($E568>0,"CLOSED",IF($D568<H$1,"ACTIVE","WAITING FOR OPEN")) -> ACTIVE | I568: =IF($E568>0,"CLOSED",IF($D568<I$1,"ACTIVE","WAITING FOR OPEN")) -> ACTIVE | J568: =IF($E568>0,"CLOSED",IF($D568<J$1,"ACTIVE","WAITING FOR OPEN")) -> ACTIVE | K568: =IF($E568>0,"CLOSED",IF($D568<K$1,"ACTIVE","WAITING FOR OPEN")) -> ACTIVE | L568: =IF($E568>0,"CLOSED",IF($D568<L$1,"ACTIVE","WAITING FOR OPEN")) -> ACTIVE | M568: =IF($E568>0,"CLOSED",IF($D568<M$1,"ACTIVE","WAITING FOR OPEN")) -> ACTIVE | ... Q568: =IF($E568>0,"CLOSED",IF($D568<Q$1,"ACTIVE","WAITING FOR OPEN")) -> ACTIVE
B569: TCHNEW004 | C569: =VLOOKUP(B569,Master!B:C,2,0) -> 1010115 | D569: =VLOOKUP(B569,Master!B:L,11,0) -> 46062 | E569: =VLOOKUP(B569,Master!B:P,15,0) -> 0 | F569: =IF($E569>0,"CLOSED",IF($D569<F$1,"ACTIVE","WAITING FOR OPEN")) -> WAITING FOR OPEN | G569: =IF($E569>0,"CLOSED",IF($D569<G$1,"ACTIVE","WAITING FOR OPEN")) -> ACTIVE | H569: =IF($E569>0,"CLOSED",IF($D569<H$1,"ACTIVE","WAITING FOR OPEN")) -> ACTIVE | I569: =IF($E569>0,"CLOSED",IF($D569<I$1,"ACTIVE","WAITING FOR OPEN")) -> ACTIVE | J569: =IF($E569>0,"CLOSED",IF($D569<J$1,"ACTIVE","WAITING FOR OPEN")) -> ACTIVE | K569: =IF($E569>0,"CLOSED",IF($D569<K$1,"ACTIVE","WAITING FOR OPEN")) -> ACTIVE | L569: =IF($E569>0,"CLOSED",IF($D569<L$1,"ACTIVE","WAITING FOR OPEN")) -> ACTIVE | M569: =IF($E569>0,"CLOSED",IF($D569<M$1,"ACTIVE","WAITING FOR OPEN")) -> ACTIVE | ... Q569: =IF($E569>0,"CLOSED",IF($D569<Q$1,"ACTIVE","WAITING FOR OPEN")) -> ACTIVE
B570: FCNEW002 | C570: =VLOOKUP(B570,Master!B:C,2,0) -> 1011821 | D570: =VLOOKUP(B570,Master!B:L,11,0) -> 46029 | E570: =VLOOKUP(B570,Master!B:P,15,0) -> 0 | F570: =IF($E570>0,"CLOSED",IF($D570<F$1,"ACTIVE","WAITING FOR OPEN")) -> ACTIVE | G570: =IF($E570>0,"CLOSED",IF($D570<G$1,"ACTIVE","WAITING FOR OPEN")) -> ACTIVE | H570: =IF($E570>0,"CLOSED",IF($D570<H$1,"ACTIVE","WAITING FOR OPEN")) -> ACTIVE | I570: =IF($E570>0,"CLOSED",IF($D570<I$1,"ACTIVE","WAITING FOR OPEN")) -> ACTIVE | J570: =IF($E570>0,"CLOSED",IF($D570<J$1,"ACTIVE","WAITING FOR OPEN")) -> ACTIVE | K570: =IF($E570>0,"CLOSED",IF($D570<K$1,"ACTIVE","WAITING FOR OPEN")) -> ACTIVE | L570: =IF($E570>0,"CLOSED",IF($D570<L$1,"ACTIVE","WAITING FOR OPEN")) -> ACTIVE | M570: =IF($E570>0,"CLOSED",IF($D570<M$1,"ACTIVE","WAITING FOR OPEN")) -> ACTIVE | ... Q570: =IF($E570>0,"CLOSED",IF($D570<Q$1,"ACTIVE","WAITING FOR OPEN")) -> ACTIVE
B571: 1011108 | C571: =VLOOKUP(B571,Master!B:C,2,0) -> 1011108 | D571: =VLOOKUP(B571,Master!B:L,11,0) -> 46036 | E571: =VLOOKUP(B571,Master!B:P,15,0) -> 0 | F571: =IF($E571>0,"CLOSED",IF($D571<F$1,"ACTIVE","WAITING FOR OPEN")) -> ACTIVE | G571: =IF($E571>0,"CLOSED",IF($D571<G$1,"ACTIVE","WAITING FOR OPEN")) -> ACTIVE | H571: =IF($E571>0,"CLOSED",IF($D571<H$1,"ACTIVE","WAITING FOR OPEN")) -> ACTIVE | I571: =IF($E571>0,"CLOSED",IF($D571<I$1,"ACTIVE","WAITING FOR OPEN")) -> ACTIVE | J571: =IF($E571>0,"CLOSED",IF($D571<J$1,"ACTIVE","WAITING FOR OPEN")) -> ACTIVE | K571: =IF($E571>0,"CLOSED",IF($D571<K$1,"ACTIVE","WAITING FOR OPEN")) -> ACTIVE | L571: =IF($E571>0,"CLOSED",IF($D571<L$1,"ACTIVE","WAITING FOR OPEN")) -> ACTIVE | M571: =IF($E571>0,"CLOSED",IF($D571<M$1,"ACTIVE","WAITING FOR OPEN")) -> ACTIVE | ... Q571: =IF($E571>0,"CLOSED",IF($D571<Q$1,"ACTIVE","WAITING FOR OPEN")) -> ACTIVE
B572: 1011716 | C572: =VLOOKUP(B572,Master!B:C,2,0) -> 1011716 | D572: =VLOOKUP(B572,Master!B:L,11,0) -> 46042 | E572: =VLOOKUP(B572,Master!B:P,15,0) -> 0 | F572: =IF($E572>0,"CLOSED",IF($D572<F$1,"ACTIVE","WAITING FOR OPEN")) -> ACTIVE | G572: =IF($E572>0,"CLOSED",IF($D572<G$1,"ACTIVE","WAITING FOR OPEN")) -> ACTIVE | H572: =IF($E572>0,"CLOSED",IF($D572<H$1,"ACTIVE","WAITING FOR OPEN")) -> ACTIVE | I572: =IF($E572>0,"CLOSED",IF($D572<I$1,"ACTIVE","WAITING FOR OPEN")) -> ACTIVE | J572: =IF($E572>0,"CLOSED",IF($D572<J$1,"ACTIVE","WAITING FOR OPEN")) -> ACTIVE | K572: =IF($E572>0,"CLOSED",IF($D572<K$1,"ACTIVE","WAITING FOR OPEN")) -> ACTIVE | L572: =IF($E572>0,"CLOSED",IF($D572<L$1,"ACTIVE","WAITING FOR OPEN")) -> ACTIVE | M572: =IF($E572>0,"CLOSED",IF($D572<M$1,"ACTIVE","WAITING FOR OPEN")) -> ACTIVE | ... Q572: =IF($E572>0,"CLOSED",IF($D572<Q$1,"ACTIVE","WAITING FOR OPEN")) -> ACTIVE
B573: 1011410 | C573: =VLOOKUP(B573,Master!B:C,2,0) -> 1011410 | D573: =VLOOKUP(B573,Master!B:L,11,0) -> 46044 | E573: =VLOOKUP(B573,Master!B:P,15,0) -> 0 | F573: =IF($E573>0,"CLOSED",IF($D573<F$1,"ACTIVE","WAITING FOR OPEN")) -> ACTIVE | G573: =IF($E573>0,"CLOSED",IF($D573<G$1,"ACTIVE","WAITING FOR OPEN")) -> ACTIVE | H573: =IF($E573>0,"CLOSED",IF($D573<H$1,"ACTIVE","WAITING FOR OPEN")) -> ACTIVE | I573: =IF($E573>0,"CLOSED",IF($D573<I$1,"ACTIVE","WAITING FOR OPEN")) -> ACTIVE | J573: =IF($E573>0,"CLOSED",IF($D573<J$1,"ACTIVE","WAITING FOR OPEN")) -> ACTIVE | K573: =IF($E573>0,"CLOSED",IF($D573<K$1,"ACTIVE","WAITING FOR OPEN")) -> ACTIVE | L573: =IF($E573>0,"CLOSED",IF($D573<L$1,"ACTIVE","WAITING FOR OPEN")) -> ACTIVE | M573: =IF($E573>0,"CLOSED",IF($D573<M$1,"ACTIVE","WAITING FOR OPEN")) -> ACTIVE | ... Q573: =IF($E573>0,"CLOSED",IF($D573<Q$1,"ACTIVE","WAITING FOR OPEN")) -> ACTIVE
B574: 50GL3601 | C574: =VLOOKUP(B574,Master!B:C,2,0) -> 50GL3601 | D574: =VLOOKUP(B574,Master!B:L,11,0) -> 45689 | E574: =VLOOKUP(B574,Master!B:P,15,0) -> 0 | F574: =IF($E574>0,"CLOSED",IF($D574<F$1,"ACTIVE","WAITING FOR OPEN")) -> ACTIVE | G574: =IF($E574>0,"CLOSED",IF($D574<G$1,"ACTIVE","WAITING FOR OPEN")) -> ACTIVE | H574: =IF($E574>0,"CLOSED",IF($D574<H$1,"ACTIVE","WAITING FOR OPEN")) -> ACTIVE | I574: =IF($E574>0,"CLOSED",IF($D574<I$1,"ACTIVE","WAITING FOR OPEN")) -> ACTIVE | J574: =IF($E574>0,"CLOSED",IF($D574<J$1,"ACTIVE","WAITING FOR OPEN")) -> ACTIVE | K574: =IF($E574>0,"CLOSED",IF($D574<K$1,"ACTIVE","WAITING FOR OPEN")) -> ACTIVE | L574: =IF($E574>0,"CLOSED",IF($D574<L$1,"ACTIVE","WAITING FOR OPEN")) -> ACTIVE | M574: =IF($E574>0,"CLOSED",IF($D574<M$1,"ACTIVE","WAITING FOR OPEN")) -> ACTIVE | ... Q574: =IF($E574>0,"CLOSED",IF($D574<Q$1,"ACTIVE","WAITING FOR OPEN")) -> ACTIVE
... B639: 10KKNOBUD13 | C639: =VLOOKUP(B639,Master!B:C,2,0) -> 10KK5063 | D639: =VLOOKUP(B639,Master!B:L,11,0) -> 46357 | E639: =VLOOKUP(B639,Master!B:P,15,0) -> 0 | F639: =IF($E639>0,"CLOSED",IF($D639<F$1,"ACTIVE","WAITING FOR OPEN")) -> WAITING FOR OPEN | G639: =IF($E639>0,"CLOSED",IF($D639<G$1,"ACTIVE","WAITING FOR OPEN")) -> WAITING FOR OPEN | H639: =IF($E639>0,"CLOSED",IF($D639<H$1,"ACTIVE","WAITING FOR OPEN")) -> WAITING FOR OPEN | I639: =IF($E639>0,"CLOSED",IF($D639<I$1,"ACTIVE","WAITING FOR OPEN")) -> WAITING FOR OPEN | J639: =IF($E639>0,"CLOSED",IF($D639<J$1,"ACTIVE","WAITING FOR OPEN")) -> WAITING FOR OPEN | K639: =IF($E639>0,"CLOSED",IF($D639<K$1,"ACTIVE","WAITING FOR OPEN")) -> WAITING FOR OPEN | L639: =IF($E639>0,"CLOSED",IF($D639<L$1,"ACTIVE","WAITING FOR OPEN")) -> WAITING FOR OPEN | M639: =IF($E639>0,"CLOSED",IF($D639<M$1,"ACTIVE","WAITING FOR OPEN")) -> WAITING FOR OPEN | ... Q639: =IF($E639>0,"CLOSED",IF($D639<Q$1,"ACTIVE","WAITING FOR OPEN")) -> ACTIVE
D640: No of stores | F640: =COUNTIFS(F3:F639,"ACTIVE") -> 561 | G640: =COUNTIFS(G3:G639,"ACTIVE") -> 568 | H640: =COUNTIFS(H3:H639,"ACTIVE") -> 570 | I640: =COUNTIFS(I3:I639,"ACTIVE") -> 587 | J640: =COUNTIFS(J3:J639,"ACTIVE") -> 602 | K640: =COUNTIFS(K3:K639,"ACTIVE") -> 610 | L640: =COUNTIFS(L3:L639,"ACTIVE") -> 618 | M640: =COUNTIFS(M3:M639,"ACTIVE") -> 622 | ... Q640: =COUNTIFS(Q3:Q639,"ACTIVE") -> 629

Sheet Sheet1

Sheet Lọc code mới
A1: Code from network + PMO | B1: Vlookup code master
A2: 2010704 | B2: =VLOOKUP(A2,Master!B:H,7,0) -> HN Nguyen Van Loc
A3: 2011001 | B3: =VLOOKUP(A3,Master!B:H,7,0) -> HN Xuan La
A4: 2010403 | B4: =VLOOKUP(A4,Master!B:H,7,0) -> HN Hao Nam
A5: 2050101 | B5: =VLOOKUP(A5,Master!B:H,7,0) -> HY Pho Truc Ecopark
A6: 2010309 | B6: =VLOOKUP(A6,Master!B:H,7,0) -> HN Vu Pham Ham
A7: 2010604 | B7: =VLOOKUP(A7,Master!B:H,7,0) -> HN Gamuda Gardens
A8: 1010712 | B8: =VLOOKUP(A8,Master!B:H,7,0) -> HCM Signature Crescent Mall
A9: 1011003 | B9: =VLOOKUP(A9,Master!B:H,7,0) -> HCM Cao Thang 2
A10: 2010402 | B10: =VLOOKUP(A10,Master!B:H,7,0) -> HN Thai Ha
A11: 1010311 | B11: =VLOOKUP(A11,Master!B:H,7,0) -> UT HCM 71 Hoang Van Thai
A12: 1011410 | B12: =VLOOKUP(A12,Master!B:H,7,0) -> UT HCM 141-143 Tan Son Nhi
A13: 1011715 | B13: =VLOOKUP(A13,Master!B:H,7,0) -> Utea Phan Huy Ích
... A637: 10KKNOBUD13 | B637: =VLOOKUP(A637,Master!B:H,7,0) -> Kichi Kichi

Sheet TCH (append)
A1: 1. Miền | B1: Mã code chính dự án | C1: Code budget | D1: 2. Tên dự án | E1: Công việc | F1: 3. Brand | G1: 4. Loại hình dự án | H1: 5. Vị trí | I1: Trạng thái thiết kế | J1: Tình trạng lập dự toán | K1: Tình trạng đấu thầu thi công | L1: Ngày kết thúc thi công theo kế hoạch | M1: Ngày bắt đầu thi công thực tế | N1: Ngày kết thúc thi công thực tế | O1: Tỉ lệ % hoàn thành thi công | P1: Tình trạng thi công
A2: NS | B2: TCH0001 | C2: 2010704 | D2: TCH + Flychef Nguyễn Văn Lộc | F2: TCH | G2: Convert | H2: Shophouse | I2: Completed | J2: Completed | K2: Completed | L2: 45976 | M2: 45933 | N2: 45991 | O2: 1 | P2: Completed
A3: NS | B3: TCH0002 | C3: 2011001 | D3: TCH HNI Can 8 Khu nha N1 Du An Xuan La Xuan Dinh | F3: TCH | G3: Reno | H3: Chân đế | I3: Completed | J3: Completed | K3: Completed | L3: 45966 | M3: 45923 | N3: 45966 | O3: 1 | P3: Completed
A4: NS | B4: TCH0003 | C4: 2010403 | D4: TCH HNI 30 Hao Nam | F4: TCH | G4: Reno | H4: Shophouse | I4: Completed | J4: Completed | K4: Completed | L4: 46002 | M4: 45980 | N4: 46002 | O4: 1 | P4: Completed
A5: NS | B5: TCH0004 | C5: 2050101 | D5: TCH HYN B65 Pho Truc | F5: TCH | G5: Reno | H5: Shophouse | I5: Completed | J5: Completed | K5: Completed | L5: 46016 | M5: 45986 | N5: 46016 | O5: 1 | P5: Completed
A6: NS | B6: TCH0005 | C6: 2010309 | D6: TCH HNI 60 Vu Pham Ham | F6: TCH | G6: Reno | H6: Shophouse | I6: Completed | J6: Completed | K6: Completed | L6: 46016 | M6: 45987 | N6: 46014 | O6: 1 | P6: Completed
A7: NS | B7: TCH0006 | C7: 2010604 | D7: TCH HNI CT1-A-01 Gamuda Gardens | F7: TCH | G7: Reno | H7: Chân đế | I7: Completed | J7: Completed | K7: Completed | L7: 46051 | M7: 46021 | N7: 46050 | O7: 1 | P7: Completed
A8: SS | B8: TCH0007 | C8: 1010712 | D8: TCH Sig 101 Ton Dat Tien (Crescent Mall) | E8: Linh báo tạm ngưng đến khi có thông tin | F8: TCH(K) & UP | G8: Convert | H8: Mall | I8: Completed | J8: Completed | K8: Completed | P8: On Hold
A9: SS | B9: TCH0008 | C9: 1011003 | D9: TCH HCM 175B Cao Thang noi dai | F9: TCH & UP | G9: Convert | H9: Shophouse | I9: Completed | J9: Not Planned | K9: On Hold | P9: On Hold
A10: NS | B10: TCH0009 | C10: 2010402 | D10: TCH HNI So 1-2 Thai Ha | F10: UP | G10: Convert | H10: Chân đế | I10: Cancelled | J10: Cancelled | K10: Cancelled | P10: On Hold
A11: SS | B11: TCH0010 | C11: 1010311 | D11: TCH HCM 71 Hoang Van Thai | F11: UT | G11: Convert | H11: Shophouse | I11: Completed | J11: Completed | K11: On Hold | P11: On Hold
A12: SS | B12: TCH0011 | C12: 1011410 | D12: TCH HCM 141-143 Tan Son Nhi | F12: UT | G12: Convert | H12: Shophouse | I12: Completed | J12: Completed | K12: Completed | L12: 46042 | M12: 46009 | N12: 46042 | O12: 1 | P12: Completed
A13: SS | B13: TCH0012 | C13: 1011715 | D13: TCH HCM 403 Phan Huy Ich | F13: UT | G13: Convert | H13: Shophouse | I13: Completed | J13: Completed | K13: Completed | L13: 46002 | M13: 45974 | N13: 46002 | O13: 1 | P13: Completed
A14: SS | B14: TCH0013 | C14: 1011716 | D14: TCH HCM 771 Phan Van Tri | F14: UT | G14: Convert | H14: Shophouse | I14: Completed | J14: Completed | K14: Completed | L14: 46039 | M14: 46008 | N14: 46039 | O14: 1 | P14: Completed
A15: SS | B15: TCH0014 | C15: 1011820 | D15: TCH HCM 75 duong D1 UT 75 NGUYỄN VĂN THƯƠNG (D1) | F15: UT | G15: Convert | H15: Shophouse | I15: Completed | J15: Completed | K15: In Progress
A16: SS | B16: TCH0015 | C16: 1011108 | D16: TCH HCM 45 Duong So 5 - Cu xa Binh Thoi | F16: UT | G16: Convert | H16: Shophouse | I16: Completed | J16: Completed | K16: Completed | L16: 46032 | M16: 46007 | N16: 46031 | O16: 1 | P16: Completed
A17: SS | B17: TCH0016 | C17: 1011819 | D17: TCH HCM 14B1 Ngo Tat To | F17: UT | G17: Convert | H17: Shophouse | I17: Cancelled | J17: Completed | K17: Cancelled | P17: Cancelled
A18: SS | B18: TCH0017 | C18: 1010211 | D18: TCH HCM 670 Nguyen Duy Trinh | F18: UT | G18: Convert | H18: Shophouse | I18: Completed | J18: Completed | K18: Completed | L18: 46010 | M18: 45975 | N18: 46008 | O18: 1 | P18: Completed
A19: SS | B19: TCH0018 | C19: 1010201 | D19: TCH HCM 57 Xuan Thuy | F19: TCH(K) & UP | G19: Convert | H19: Shophouse | I19: Completed | J19: Completed | K19: Completed | L19: 46044 | M19: 45996 | N19: 46044 | O19: 1 | P19: Completed
A20: SS | B20: TCH0019 | C20: 1011107 | D20: TCH HCM 64A Lu Gia | F20: TCH | G20: Cosmetic | H20: Shophouse | I20: Completed | J20: Completed | K20: Completed | L20: 46068 | M20: 46051 | N20: 46060 | O20: 1 | P20: Completed
A21: SS | B21: TCH0020 | C21: 1011007 | D21: TCH HCM 25A duong Dong Nai | F21: TCH | G21: Cosmetic | H21: Shophouse | I21: Completed | J21: Not Planned | K21: On Hold | P21: On Hold
A22: SS | B22: TCH0021 | C22: 1010703 | D22: TCH HCM 492 Nguyen Thi Thap | E22: Đang chờ duyệt phát sinh, dự kiến tiến độ bàn giao qua tết | F22: TCH | G22: Cosmetic | H22: Shophouse | I22: Completed | J22: Not Planned | K22: Completed | L22: 46071 | M22: 46041 | N22: 46063 | O22: 1 | P22: Completed
A23: SS | B23: TCH0022 | C23: 1011310 | D23: TCH HCM 4-6 Ap Bac | F23: TCH | G23: Cosmetic | H23: Shophouse | I23: Completed | J23: Not Planned | K23: Completed | L23: 46064 | M23: 46039 | N23: 46064 | O23: 1 | P23: Completed
A24: SS | B24: TCH0023 | C24: 1011313 | D24: TCH HCM 51 Le Trung Nghia | F24: TCH | G24: Cosmetic | H24: Shophouse | I24: Completed | J24: Completed | K24: Completed | L24: 46058 | M24: 46027 | N24: 46058 | O24: 1 | P24: Completed
A25: SS | B25: TCH0024 | C25: 1011705 | D25: TCH HCM 190B1 Phan Van Tri | E25: Nhà hàng bàn giao MB ngày 20/1/26 | F25: TCH | G25: Cosmetic | H25: Shophouse | I25: Completed | J25: Not Planned | K25: Completed | L25: 46067 | M25: 46042 | N25: 46067 | O25: 1 | P25: Completed
A26: SS | B26: TCH0025 | C26: 1011301 | D26: TCH HCM 02 Dong Da | F26: TCH | G26: Cosmetic | H26: Shophouse | I26: Completed | J26: Completed | K26: Completed | L26: 46053 | M26: 46027 | O26: 1 | P26: Completed
A27: SS | B27: TCH0026 | C27: 1010209 | D27: TCH HCM Homyland Riverside | F27: TCH | G27: Cosmetic | H27: Chân đế | I27: Completed | J27: Completed | K27: Completed | L27: 46058 | M27: 46043 | O27: 1 | P27: Completed
A28: SS | B28: TCH0027 | C28: 1010601 | D28: TCH HCM 178 Hau Giang | E28: ĐTXD thông báo 14/1/26, đầu tuần nhà thầu báo lại tiến độ | F28: TCH | G28: Cosmetic | H28: Shophouse | I28: Completed | J28: Not Planned | K28: Completed | L28: 46063 | M28: 46051 | N28: 46063 | O28: 1 | P28: Completed
A29: SS | B29: TCH0028 | C29: 1010304 | D29: TCH HCM 6A Ngo Thoi Nhiem | F29: TCH | G29: Reno | H29: Shophouse | I29: Completed | J29: Completed | K29: Completed | L29: 46062 | M29: 46035 | N29: 46061 | O29: 1 | P29: Completed
A30: SS | B30: TCH0029 | C30: 1010207 | D30: TCH HCM 17 Mai Chi Tho | E30: dự kiến tuần này xin phép xong | F30: TCH | G30: Cosmetic | H30: Chân đế | I30: Completed | J30: Not Planned | K30: Completed | L30: 46075 | M30: 46048 | N30: 46067 | O30: 1 | P30: Completed
A31: SS | B31: TCH0030 | C31: 1010901 | D31: TCH HCM 359 Do Xuan Hop | E31: 7/2/26 inox mới bàn giao | F31: TCH | G31: Cosmetic | H31: Shophouse | I31: Completed | J31: Completed | K31: Completed | L31: 46057 | M31: 46021 | N31: 46059 | O31: 1 | P31: Completed
A32: SS | B32: TCH0031 | C32: 3060101 | D32: TCH TNH 295 Duong 30/4 | F32: TCH | G32: Cosmetic | H32: Shophouse | I32: Completed | J32: Not Planned | K32: In Progress
A33: SS | B33: TCH0032 | C33: 1010603 | D33: TCH HCM 111-113 Binh Phu | E33: ĐTXD thông báo thầu 11/3, qua tuần họp kickoff sẽ báo lại tiến độ | F33: TCH | G33: Cosmetic | H33: Shophouse | I33: Completed | J33: Not Planned | K33: Completed | L33: 46139 | O33: 0 | P33: In Progress
A34: SS | B34: TCH0033 | C34: 1011603 | D34: TCH HCM 68 Huynh Van Banh | F34: TCH | G34: Cosmetic | H34: Shophouse | I34: Completed | J34: Not Planned | K34: Cancelled | P34: Cancelled
A35: SS | B35: TCH0034 | C35: 3020101 | D35: TCH BRU 5 Ba Cu | F35: TCH | G35: Cosmetic | H35: Shophouse | I35: Completed | J35: Not Planned | K35: Completed | P35: In Progress
A36: SS | B36: TCH0035 | C36: 4030101 | D36: TCH KHA 44 Tran Phu | F36: TCH | G36: Cosmetic | I36: Completed | J36: Not Planned | K36: In Progress
A37: SS | B37: TCH0036 | C37: 1011605 | D37: TCH HCM So 1 Hoa Su | F37: TCH | G37: Cosmetic | H37: Shophouse | I37: Completed | J37: Completed | K37: Completed | L37: 46056 | M37: 46021 | O37: 1 | P37: Completed
A38: SS | B38: TCH0037 | C38: 1011904 | D38: TCH HCM 66E Hoang Dieu 2 | F38: TCH | G38: Cosmetic | H38: Shophouse | I38: Completed | J38: Completed | K38: Completed | L38: 46056 | M38: 46021 | O38: 1 | P38: Completed
A39: SS | B39: TCH0038 | C39: 1012001 | D39: TCH HCM 114 Duong 9A - Trung Son | E39: Đã họp Kickoff, hiện đang tiến hành trình duyệt phát sinh theo y/c TK, Ops, AMM, thực tế,.... Tiến độ dự kiến báo lại sau, NCC báo duyệt phát sinh mới tiến hành làm và gửi tiến độ thi công cụ thể | F39: TCH | G39: Cosmetic | H39: Shophouse | I39: Completed | J39: Not Planned | K39: Completed | L39: 46119 | M39: 46098 | O39: 0.1 | P39: In Progress
A40: SS | B40: TCH0039 | C40: 3010102 | D40: TCH DNI R132 Vo Thi Sau | E40: Chưa nhận được thông báo thầu | F40: TCH | G40: Cosmetic | I40: Completed | J40: Not Planned | K40: Completed
...

Sheet Sheet3
C3: Master hiện tại
C4: Plan NSO theo budget - code budget lấy theo budget - code PC lookup sang file tracking CAPEX

Sheet Plan 2026
A1: ID | B1: Code Budget | C1: Tên brand | D1: BU See | E1: Năm offer MB | F1: Quý offer MB | G1: Tháng offer MB | H1: Tháng Khai trương dự kiến | I1: Tháng Khai trương thực tế | J1: Vùng | K1: Miền | L1: Tỉnh, TP | M1: Mã tỉnh 2024 | N1: Quận, huyện | O1: Phường, xã | P1: Trục đường chính | Q1: Loại hình | R1: Mặt tiền (m) | S1: Mặt tiền (chuẩn hóa) | T1: Diện tích (m2) | U1: Diện tích (chuẩn hóa) | V1: Số lượng site plan | W1: Plan/out of plan | X1: Tên mall/site | Y1: Tên mall (chuẩn hóa) | Z1: Giá thuê lấy từ std format | AA1: Giá thuê mong muốn | AB1: New/Convert/Share | AC1: Tình trạng | AD1: Ngày ký HĐ | AE1: Count | AF1: Ghi chú | AG1: Phường tự thêm | AH1: Viết tắt brand | AI1: Date | AJ1: Tháng offer | AK1: Address | AL1: Địa chỉ đầy đủ | AM1: Mã phường 2024 | AN1: Brand and Type format | AO1: Key | AP1: Mật độ tầng lớp tiêu dùng người/km2 | AQ1: Ranking phường theo tỉnh 2024 | AR1: Ranking phường toàn quốc 2024 | AS1: Số lượng cửa hàng hoạt động | AT1: Ranking theo brands | AU1: Daily Sales forecast (mil) - NW | AV1: Giá thuê | AW1: Tên site
A2: 1 | B2: 30GGNEW64 | C2: Gogi House | D2: Võ Đang Nhị Hiệp Trần Tuấn Sĩ Lương Anh Lộc Võ Hoàng Dũng Nguyễn Thị Phượng | E2: 2026 | F2: 3 | G2: 8 | H2: 12 | J2: SBU.MN | K2: Nam | L2: An Giang | M2: VNM.1_1 | N2: Châu Đốc | O2: Châu Phú B | Q2: Shophouse | R2: 8 | S2: 6 - 8 | T2: 220 - 240 | U2: 200 - 300 | V2: 1 | W2: UT1 | X2: Trưng Nữ Vương-Châu Đốc-AG | Z2: - | AB2: New | AC2: Reject | AE2: 0 | AF2: Đất nông nghiệp, đang phải tìm site mới | AH2: GG | AI2: 46235 | AJ2: 8 | AK2: Châu Phú B, Châu Đốc, An Giang | AL2: Châu Phú B, Châu Đốc, An Giang | AM2: VNM.1.3.2_1 | AN2: Gogi House Shophouse | AO2: Gogi House|Châu Phú B, Châu Đốc, An Giang | AP2: 580 | AQ2: 15/156 | AR2: 1360/11159 | AS2: 144 | AT2: 139/144 | AW2: =Plan_2026[[#This Row],[Tên brand]]&" "&Plan_2026[[#This Row],[Trục đường chính]]&Plan_2026[[#This Row],[Tên mall (chuẩn hóa)]]&Plan_2026[[#This Row],[Địa chỉ đầy đủ]] -> Gogi House Châu Phú B, Châu Đốc, An Giang
A3: 2 | B3: 30CDNOBUD2 | C3: CloudPot | D3: Lê Thị Như Bích | E3: 2026 | F3: 3 | G3: 7 | H3: 11 | J3: SBU.MN | K3: Nam | L3: An Giang | M3: VNM.1_1 | N3: Long Xuyên | O3: Mỹ Bình | P3: Số 1242, Đường Trần Hưng Đạo | Q3: Mall | R3: 6 | S3: <= 6 | T3: 200 - 240 | U3: 200 - 300 | V3: 1 | W3: UT2 | X3: Vincom An Giang | Y3: Vincom Plaza Long Xuyên | Z3: 180 | AB3: New | AC3: Chưa có | AE3: 0 | AF3: NWS có sẽ offer | AH3: CD | AI3: 46204 | AJ3: 7 | AK3: Mỹ Bình, Long Xuyên, An Giang | AL3: Số 1242, Đường Trần Hưng Đạo, Mỹ Bình, Long Xuyên, An Giang | AM3: VNM.1.6.4_1 | AN3: CloudPot Mall | AO3: CloudPot|Vincom Plaza Long Xuyên | AP3: 5022 | AQ3: 4/156 | AR3: 511/11159 | AS3: 17 | AT3: 13/17 | AW3: =Plan_2026[[#This Row],[Tên brand]]&" "&Plan_2026[[#This Row],[Trục đường chính]]&Plan_2026[[#This Row],[Tên mall (chuẩn hóa)]]&Plan_2026[[#This Row],[Địa chỉ đầy đủ]] -> CloudPot Số 1242, Đường Trần Hưng ĐạoVincom Plaza Long XuyênSố 1242, Đường Trần Hưng Đạo, Mỹ Bình, Long Xuyên, An Giang
A4: 3 | B4: 30SSNOBUD01 | C4: Isushi | D4: Nguyễn Thế Nguyên Nguyễn Thị Kim Luyện | E4: 2026 | F4: 3 | G4: 7 | H4: 11 | J4: SBU.MN | K4: Nam | L4: An Giang | M4: VNM.1_1 | N4: Long Xuyên | O4: Mỹ Bình | P4: 1242 Trần Hưng Đạo | Q4: Mall | R4: 8 - 12 | S4: 8 - 12 | T4: 200 - 300 | U4: 200 - 300 | V4: 1 | W4: UT2 | X4: Vincom Plaza Long Xuyên | Y4: Vincom Plaza Long Xuyên | Z4: 300 | AB4: New | AC4: Chưa có | AE4: 0 | AH4: SS | AI4: 46204 | AJ4: 7 | AK4: Mỹ Bình, Long Xuyên, An Giang | AL4: 1242 Trần Hưng Đạo, Mỹ Bình, Long Xuyên, An Giang | AM4: VNM.1.6.4_1 | AN4: Isushi Mall | AO4: Isushi|Vincom Plaza Long Xuyên | AP4: 5022 | AQ4: 4/156 | AR4: 511/11159 | AS4: 25 | AT4: 17/25 | AW4: =Plan_2026[[#This Row],[Tên brand]]&" "&Plan_2026[[#This Row],[Trục đường chính]]&Plan_2026[[#This Row],[Tên mall (chuẩn hóa)]]&Plan_2026[[#This Row],[Địa chỉ đầy đủ]] -> Isushi 1242 Trần Hưng ĐạoVincom Plaza Long Xuyên1242 Trần Hưng Đạo, Mỹ Bình, Long Xuyên, An Giang
A5: 377 | B5: 30DNNOBUD06 | C5: Dao Niu Guo | D5: Lê Thị Như Bích | E5: 2026 | F5: 1 | G5: 2 | H5: 6 | J5: SBU.MN | K5: Nam | L5: Bà Rịa - Vũng Tàu | M5: VNM.7_1 | N5: Vũng Tàu | O5: Phường 8 | P5: 251 – 251A Thống Nhất Mới. | Q5: Shophouse | R5: 8 - 12 | S5: 8 - 12 | T5: 300 | U5: 300 - 500 | V5: 1 | W5: UT2 | Z5: 160 | AB5: Convert | AC5: Đã ký | AE5: 1 | AF5: Convert từ Kpub | AH5: DN | AI5: 46054 | AJ5: 2 | AK5: Phường 8, Vũng Tàu, Bà Rịa - Vũng Tàu | AM5: VNM.7.6.12_1 | AN5: Dao Niu Guo Shophouse | AO5: Dao Niu Guo|Phường 8, Vũng Tàu, Bà Rịa - Vũng Tàu | AP5: 7919 | AQ5: 4/82 | AR5: 359/11159 | AS5: 6 | AT5: 4/6 | AW5: =Plan_2026[[#This Row],[Tên brand]]&" "&Plan_2026[[#This Row],[Trục đường chính]]&Plan_2026[[#This Row],[Tên mall (chuẩn hóa)]]&Plan_2026[[#This Row],[Địa chỉ đầy đủ]] -> Dao Niu Guo 251 – 251A Thống Nhất Mới.
A6: 4 | B6: 10MWNEW18 | C6: Manwah | D6: Nguyễn Tuấn Dũng | E6: 2025 | F6: 4 | G6: 10 | H6: 2 | I6: 2 | J6: SBU.MB | K6: Bắc | L6: Bắc Giang | M6: VNM.3_1 | N6: Bắc Giang | O6: Ngô Quyền | Q6: Shophouse | R6: 8 - 12 | S6: 8 - 12 | T6: 200 - 300 | U6: 200 - 300 | V6: 1 | W6: UT1 | Z6: 200 | AB6: Convert | AC6: Hủy bỏ | AE6: 0 | AF6: Convert từ Hutong | AH6: MW | AI6: 45931 | AJ6: 10 | AK6: Ngô Quyền, Bắc Giang, Bắc Giang | AL6: Ngô Quyền, Bắc Giang, Bắc Giang | AM6: VNM.3.1.8_1 | AN6: Manwah Shophouse | AO6: Manwah|Ngô Quyền, Bắc Giang, Bắc Giang | AP6: 8350 | AQ6: 1/232 | AR6: 344/11159 | AS6: 55 | AT6: 30/55 | AW6: =Plan_2026[[#This Row],[Tên brand]]&" "&Plan_2026[[#This Row],[Trục đường chính]]&Plan_2026[[#This Row],[Tên mall (chuẩn hóa)]]&Plan_2026[[#This Row],[Địa chỉ đầy đủ]] -> Manwah Ngô Quyền, Bắc Giang, Bắc Giang
A7: 5 | B7: TCHNEW066 | C7: The Coffee House | D7: Nguyễn Thị Thanh | E7: 2026 | F7: 2 | G7: 6 | H7: 10 | J7: SBU.MB | K7: Bắc | L7: Bắc Giang | M7: VNM.3_1 | N7: Bắc Giang | O7: Ngô Quyền | P7: Ngô Gia Tự, Hùng Vương | Q7: Shophouse | R7: 8 - 12 | S7: 8 - 12 | T7: 150 - 200 | U7: 150 - 200 | V7: 1 | W7: UT1 | Z7: 132 | AB7: New | AC7: Chưa có | AE7: 0 | AF7: Khu vực TT TP Ngô Gia Tự, Hùng Vương (shop house, chân đế, mall) | AH7: TCH | AI7: 46174 | AJ7: 6 | AK7: Ngô Quyền, Bắc Giang, Bắc Giang | AL7: Ngô Gia Tự, Hùng Vương, Ngô Quyền, Bắc Giang, Bắc Giang | AM7: VNM.3.1.8_1 | AN7: The Coffee House Shophouse | AO7: The Coffee House|Ngô Quyền, Bắc Giang, Bắc Giang | AP7: 8350 | AQ7: 1/232 | AR7: 344/11159 | AS7: 81 | AT7: 52/81 | AW7: =Plan_2026[[#This Row],[Tên brand]]&" "&Plan_2026[[#This Row],[Trục đường chính]]&Plan_2026[[#This Row],[Tên mall (chuẩn hóa)]]&Plan_2026[[#This Row],[Địa chỉ đầy đủ]] -> The Coffee House Ngô Gia Tự, Hùng VươngNgô Gia Tự, Hùng Vương, Ngô Quyền, Bắc Giang, Bắc Giang
A8: 6 | B8: TCHNEW058 | C8: The Coffee House | D8: Nguyễn Thị Thanh | E8: 2026 | F8: 2 | G8: 5 | H8: 9 | J8: SBU.MB | K8: Bắc | L8: Bắc Ninh | M8: VNM.5_1 | N8: Từ Sơn | O8: Đông Ngàn | Q8: Mall | R8: 6 - 8 | S8: 6 - 8 | T8: 100 - 150 | U8: 100 - 150 | V8: 1 | W8: UT1 | X8: Go Từ Sơn | Y8: Go! Từ Sơn | Z8: 132 | AB8: New | AC8: Chưa có | AE8: 0 | AH8: TCH | AI8: 46143 | AJ8: 5 | AK8: Đông Ngàn, Từ Sơn, Bắc Ninh | AL8: Đông Ngàn, Từ Sơn, Bắc Ninh | AM8: VNM.5.5.5_1 | AN8: The Coffee House Mall | AO8: The Coffee House|Go! Từ Sơn | AP8: 3923 | AQ8: 6/126 | AR8: 608/11159 | AS8: 81 | AT8: 65/81 | AW8: =Plan_2026[[#This Row],[Tên brand]]&" "&Plan_2026[[#This Row],[Trục đường chính]]&Plan_2026[[#This Row],[Tên mall (chuẩn hóa)]]&Plan_2026[[#This Row],[Địa chỉ đầy đủ]] -> The Coffee House Go! Từ SơnĐông Ngàn, Từ Sơn, Bắc Ninh
A9: 7 | B9: TCHNEW005 | C9: The Coffee House | D9: Nguyễn Thị Thanh | E9: 2025 | F9: 4 | G9: 12 | H9: 4 | J9: SBU.MB | K9: Bắc | L9: Bắc Ninh | M9: VNM.5_1 | N9: Bắc Ninh | O9: Đại Phúc | P9: Lý Thái Tổ (gần Vincom) | Q9: Chân đế | R9: 6 - 8 | S9: 6 - 8 | T9: 100 - 150 | U9: 100 - 150 | V9: 1 | W9: UT2 | Z9: 132 | AB9: New | AC9: Chưa có | AE9: 0 | AH9: TCH | AI9: 45992 | AJ9: 12 | AK9: Đại Phúc, Bắc Ninh, Bắc Ninh | AL9: Lý Thái Tổ (gần Vincom), Đại Phúc, Bắc Ninh, Bắc Ninh | AM9: VNM.5.1.1_1 | AN9: The Coffee House Chân đế | AO9: The Coffee House|Đại Phúc, Bắc Ninh, Bắc Ninh | AP9: 2191 | AQ9: 9/126 | AR9: 803/11159 | AS9: 81 | AT9: 73/81 | AW9: =Plan_2026[[#This Row],[Tên brand]]&" "&Plan_2026[[#This Row],[Trục đường chính]]&Plan_2026[[#This Row],[Tên mall (chuẩn hóa)]]&Plan_2026[[#This Row],[Địa chỉ đầy đủ]] -> The Coffee House Lý Thái Tổ (gần Vincom)Lý Thái Tổ (gần Vincom), Đại Phúc, Bắc Ninh, Bắc Ninh
A10: 8 | B10: 10KKNOBUD01 | C10: Kichi Kichi | D10: Phan Văn Thủy Hà Mỹ Phượng | E10: 2026 | F10: 3 | G10: 8 | H10: 12 | J10: SBU.MB | K10: Bắc | L10: Bắc Ninh | M10: VNM.5_1 | N10: Bắc Ninh | O10: Tiền An | Q10: Chân đế | R10: 8 - 12 | S10: 8 - 12 | T10: 180 - 200 | U10: 150 - 200 | V10: 1 | W10: UT2 | Z10: - | AB10: New | AC10: Chưa có | AE10: 0 | AF10: Tránh khu Ng Đăng Đạo | AH10: KK | AI10: 46235 | AJ10: 8 | AK10: Tiền An, Bắc Ninh, Bắc Ninh | AL10: Tiền An, Bắc Ninh, Bắc Ninh | AM10: VNM.5.1.14_1 | AN10: Kichi Kichi Chân đế | AO10: Kichi Kichi|Tiền An, Bắc Ninh, Bắc Ninh | AP10: 10189 | AQ10: 1/126 | AR10: 287/11159 | AS10: 107 | AT10: 36/107 | AW10: =Plan_2026[[#This Row],[Tên brand]]&" "&Plan_2026[[#This Row],[Trục đường chính]]&Plan_2026[[#This Row],[Tên mall (chuẩn hóa)]]&Plan_2026[[#This Row],[Địa chỉ đầy đủ]] -> Kichi Kichi Tiền An, Bắc Ninh, Bắc Ninh
A11: 376 | B11: 10DNNOBUD07 | C11: Dao Niu Guo | D11: Nguyễn Ngọc Hà | E11: 2026 | F11: 1 | G11: 2 | H11: 6 | J11: SBU.MB | K11: Bắc | L11: Bắc Ninh | M11: VNM.5_1 | N11: Bắc Ninh | O11: Tiền An | Q11: Shophouse | R11: 8 - 12 | S11: 8 - 12 | T11: 300 | U11: 300 - 500 | V11: 1 | W11: UT2 | Z11: 160 | AB11: Convert | AC11: Đã ký | AE11: 1 | AF11: Convert từ Shogun | AH11: DN | AI11: 46054 | AJ11: 2 | AK11: Tiền An, Bắc Ninh, Bắc Ninh | AM11: VNM.5.1.14_1 | AN11: Dao Niu Guo Shophouse | AO11: Dao Niu Guo|Tiền An, Bắc Ninh, Bắc Ninh | AP11: 10189 | AQ11: 1/126 | AR11: 287/11159 | AS11: 6 | AT11: 3/6 | AW11: =Plan_2026[[#This Row],[Tên brand]]&" "&Plan_2026[[#This Row],[Trục đường chính]]&Plan_2026[[#This Row],[Tên mall (chuẩn hóa)]]&Plan_2026[[#This Row],[Địa chỉ đầy đủ]] -> Dao Niu Guo
A12: 9 | B12: TCHNOBUD02 | C12: The Coffee House | D12: Phạm Thanh Trúc | E12: 2026 | F12: 3 | G12: 7 | H12: 11 | J12: SBU.MN | K12: Nam | L12: Bình Định | M12: VNM.8_1 | N12: Qui Nhơn | O12: Lê Lợi | P12: Nguyễn Tất Thành/Nguyễn Trãi/Lê Lợi | Q12: Shophouse | R12: 8 - 12 | S12: 8 - 12 | T12: 150 - 200 | U12: 150 - 200 | V12: 1 | W12: UT2 | Z12: 132 | AB12: New | AC12: Chưa có | AE12: 0 | AH12: TCH | AI12: 46204 | AJ12: 7 | AK12: Lê Lợi, Qui Nhơn, Bình Định | AL12: Nguyễn Tất Thành/Nguyễn Trãi/Lê Lợi, Lê Lợi, Qui Nhơn, Bình Định | AM12: VNM.8.7.6_1 | AN12: The Coffee House Shophouse | AO12: The Coffee House|Lê Lợi, Qui Nhơn, Bình Định | AP12: 8740 | AQ12: 2/159 | AR12: 334/11159 | AS12: 81 | AT12: 52/81 | AW12: =Plan_2026[[#This Row],[Tên brand]]&" "&Plan_2026[[#This Row],[Trục đường chính]]&Plan_2026[[#This Row],[Tên mall (chuẩn hóa)]]&Plan_2026[[#This Row],[Địa chỉ đầy đủ]] -> The Coffee House Nguyễn Tất Thành/Nguyễn Trãi/Lê LợiNguyễn Tất Thành/Nguyễn Trãi/Lê Lợi, Lê Lợi, Qui Nhơn, Bình Định
A13: 10 | B13: 30WYNOBUD05 | C13: Wow!Yakiniku | D13: Bùi Hồng Gấm | E13: 2026 | F13: 2 | G13: 4 | H13: 8 | J13: SBU.MN | K13: Nam | L13: Bình Dương | M13: VNM.9_1 | N13: Thuận An | O13: Thuận Giao | P13: Thuận Giao | Q13: Mall | R13: 8 - 12 | S13: 8 - 12 | T13: 150 - 200 | U13: 150 - 200 | V13: 1 | W13: UT2 | X13: Aeon Bình Dương | Y13: Aeon Mall Bình Dương Canary | Z13: - | AB13: Share | AC13: Đã ký | AE13: 1 | AF13: Share với Sumo check lại thời gian tái ký gia hạn sửa chữa, áp concept | AH13: WY | AI13: 46113 | AJ13: 4 | AK13: Thuận Giao, Thuận An, Bình Dương | AL13: Thuận Giao, Thuận Giao, Thuận An, Bình Dương | AM13: VNM.9.9.9_1 | AN13: Wow!Yakiniku Mall | AO13: Wow!Yakiniku|Aeon Mall Bình Dương Canary | AP13: 928 | AQ13: 23/91 | AR13: 1111/11159 | AS13: 2 | AT13: 3/2 | AW13: =Plan_2026[[#This Row],[Tên brand]]&" "&Plan_2026[[#This Row],[Trục đường chính]]&Plan_2026[[#This Row],[Tên mall (chuẩn hóa)]]&Plan_2026[[#This Row],[Địa chỉ đầy đủ]] -> Wow!Yakiniku Thuận GiaoAeon Mall Bình Dương CanaryThuận Giao, Thuận Giao, Thuận An, Bình Dương
A14: 11 | B14: 30MWNOBUD01 | C14: Manwah | D14: Nguyễn Văn Bạch Long | E14: 2026 | F14: 1 | G14: 1 | H14: 5 | J14: SBU.MN | K14: Nam | L14: Bình Dương | M14: VNM.9_1 | N14: Dĩ An | O14: Đông Hòa | P14: Thống Nhất | Q14: Chân đế | R14: 8 - 12 | S14: 8 - 12 | T14: 200 - 300 | U14: 200 - 300 | V14: 1 | W14: UT1 | Z14: 200 | AB14: New | AC14: Chưa có | AE14: 0 | AF14: Phức hợp Bcon Làng đại hoc - New building | AH14: MW | AI14: 46023 | AJ14: 1 | AK14: Đông Hòa, Dĩ An, Bình Dương | AL14: Thống Nhất, Đông Hòa, Dĩ An, Bình Dương | AM14: VNM.9.5.5_1 | AN14: Manwah Chân đế | AO14: Manwah|Đông Hòa, Dĩ An, Bình Dương | AP14: 2696 | AQ14: 8/91 | AR14: 722/11159 | AS14: 55 | AT14: 44/55 | AW14: =Plan_2026[[#This Row],[Tên brand]]&" "&Plan_2026[[#This Row],[Trục đường chính]]&Plan_2026[[#This Row],[Tên mall (chuẩn hóa)]]&Plan_2026[[#This Row],[Địa chỉ đầy đủ]] -> Manwah Thống NhấtThống Nhất, Đông Hòa, Dĩ An, Bình Dương
A15: 12 | B15: 30YT4995 | C15: Yutang | D15: Võ Hoàng Dũng | E15: 2025 | F15: 4 | G15: 10 | H15: 2 | J15: SBU.MN | K15: Nam | L15: Bình Dương | M15: VNM.9_1 | N15: Dĩ An | O15: Đông Hòa | P15: Thống Nhất | Q15: Chân đế | R15: 8 | S15: 6 - 8 | T15: 120 - 150 | U15: 100 - 150 | V15: 1 | W15: UT2 | X15: Bcons Bình Dương | Z15: - | AB15: New | AC15: Đã ký | AE15: 1 | AH15: YT | AI15: 45931 | AJ15: 10 | AK15: Đông Hòa, Dĩ An, Bình Dương | AL15: Thống Nhất, Đông Hòa, Dĩ An, Bình Dương | AM15: VNM.9.5.5_1 | AN15: Yutang Chân đế | AO15: Yutang|Đông Hòa, Dĩ An, Bình Dương | AP15: 2696 | AQ15: 8/91 | AR15: 722/11159 | AS15: 10 | AT15: 6/10 | AW15: =Plan_2026[[#This Row],[Tên brand]]&" "&Plan_2026[[#This Row],[Trục đường chính]]&Plan_2026[[#This Row],[Tên mall (chuẩn hóa)]]&Plan_2026[[#This Row],[Địa chỉ đầy đủ]] -> Yutang Thống NhấtThống Nhất, Đông Hòa, Dĩ An, Bình Dương
A16: 13 | B16: TCHNOBUD03 | C16: The Coffee House | D16: Phạm Thanh Trúc | E16: 2026 | F16: 3 | G16: 7 | H16: 11 | J16: SBU.MN | K16: Nam | L16: Bình Dương | M16: VNM.9_1 | N16: Dĩ An | O16: Đông Hòa | P16: Đường Thống Nhất | Q16: Shophouse | R16: 8 - 12 | S16: 8 - 12 | T16: 150 - 200 | U16: 150 - 200 | V16: 1 | W16: UT2 | X16: Bcons Bình Dương | Z16: 132 | AB16: New | AC16: Chưa có | AE16: 0 | AF16: Cuối năm 2026 mới lấy được site site: 50 tr - 130m2 | AH16: TCH | AI16: 46204 | AJ16: 7 | AK16: Đông Hòa, Dĩ An, Bình Dương | AL16: Đường Thống Nhất, Đông Hòa, Dĩ An, Bình Dương | AM16: VNM.9.5.5_1 | AN16: The Coffee House Shophouse | AO16: The Coffee House|Đông Hòa, Dĩ An, Bình Dương | AP16: 2696 | AQ16: 8/91 | AR16: 722/11159 | AS16: 81 | AT16: 67/81 | AW16: =Plan_2026[[#This Row],[Tên brand]]&" "&Plan_2026[[#This Row],[Trục đường chính]]&Plan_2026[[#This Row],[Tên mall (chuẩn hóa)]]&Plan_2026[[#This Row],[Địa chỉ đầy đủ]] -> The Coffee House Đường Thống NhấtĐường Thống Nhất, Đông Hòa, Dĩ An, Bình Dương
A17: 14 | B17: 30GGNOBUD07 | C17: Gogi House | D17: Võ Đang Nhị Hiệp Trần Tuấn Sĩ Lương Anh Lộc Võ Hoàng Dũng Nguyễn Thị Phượng | E17: 2026 | F17: 3 | G17: 7 | H17: 11 | J17: SBU.MN | K17: Nam | L17: Bình Dương | M17: VNM.9_1 | N17: Tân Uyên | O17: Khánh Bình | Q17: Shophouse | R17: 8 | S17: 6 - 8 | T17: 200-220 | U17: 200 - 300 | V17: 1 | W17: UT2 | X17: Đường 13 Tân Uyên Bình Dương | Z17: - | AA17: 40-60tr | AB17: New | AC17: Reject | AE17: 0 | AF17: Chê MB nhỏ, muốn đi chung vs Gogi, KK chung Thủ Dầu Một, giáp Bình Chuẩn, Tân Phúc Khanh mặt tiền rộng, bãi đỗ xe MB kết hợp vs Gogi, Kichi, thành cụm | AH17: GG | AI17: 46204 | AJ17: 7 | AK17: Khánh Bình, Tân Uyên, Bình Dương | AL17: Khánh Bình, Tân Uyên, Bình Dương | AM17: VNM.9.7.3_1 | AN17: Gogi House Shophouse | AO17: Gogi House|Khánh Bình, Tân Uyên, Bình Dương | AP17: 175 | AQ17: 46/91 | AR17: 2766/11159 | AS17: 144 | AT17: 145/144 | AW17: =Plan_2026[[#This Row],[Tên brand]]&" "&Plan_2026[[#This Row],[Trục đường chính]]&Plan_2026[[#This Row],[Tên mall (chuẩn hóa)]]&Plan_2026[[#This Row],[Địa chỉ đầy đủ]] -> Gogi House Khánh Bình, Tân Uyên, Bình Dương
